Workbook

Sheet Resumo executivo
A1: Relatório econômico-fiscal do Brasil – 2016 × 2019 × 2022 × 2025
A2: Escopo nacional; contas públicas com prioridade à União/Governo Central. Dados acessados em 22/09/2026. Valores nominais do próprio ano; correção pelo IPCA até dez/2025.
A4: Parâmetros de cálculo | B4: 2016 | C4: 2019 | D4: 2022 | E4: 2025
A5: PIB (R$ bi, IBGE SIDRA 1846) | B5: 6269.327 | C5: 7389.131 | D5: 10079.676 | E5: 12738.566
A6: IPCA número-índice de dezembro (SIDRA 1737) | B6: 4775.7 | C6: 5320.25 | D6: 6474.09 | E6: 7403.29
A7: Fator IPCA dez/ano → dez/2025 | B7: =IPCA_DEZ_2025/IPCA_DEZ_2016 -> 1.5502 | C7: =IPCA_DEZ_2025/IPCA_DEZ_2019 -> 1.3915305 | D7: =IPCA_DEZ_2025/IPCA_DEZ_2022 -> 1.143526 | E7: =IPCA_DEZ_2025/IPCA_DEZ_2025 -> 1
A8: PTAX média anual (R$/US$, média das médias mensais – BCB SGS 3698) | B8: =AVERAGE(4.0524,3.9737,3.7039,3.5658,3.5393,3.4245,3.2756,3.2097,3.2564,3.1858,3.342,3.3523) -> 3.4901167 | C8: =AVERAGE(3.7417,3.7236,3.8465,3.8962,4.0015,3.8588,3.7793,4.02,4.1215,4.087,4.1553,4.1096) -> 3.9450833 | D8: =AVERAGE(5.5341,5.1966,4.9684,4.758,4.9551,5.0492,5.3681,5.1433,5.237,5.2503,5.2747,5.2424) -> 5.1647667 | E8: =AVERAGE(6.0218,5.7656,5.7468,5.7837,5.6674,5.5471,5.5285,5.4469,5.3674,5.3855,5.3409,5.4531) -> 5.5878917
A9: PIB em US$ bi | B9: =PIB_2016/PTAX_2016 -> 1796.3087 | C9: =PIB_2019/PTAX_2019 -> 1872.9974 | D9: =PIB_2022/PTAX_2022 -> 1951.6227 | E9: =PIB_2025/PTAX_2025 -> 2279.673
A11: Principais indicadores
A12: Indicador | B12: 2016 | C12: 2019 | D12: 2022 | E12: 2025 | F12: Var. real 2016→2019 | G12: Var. real 2019→2022 | H12: Var. real 2022→2025 | I12: Leitura
A13: PIB (R$ bi) | B13: ='PIB setorial'!F4 -> 6269.327 | C13: ='PIB setorial'!G4 -> 7389.131 | D13: ='PIB setorial'!H4 -> 10079.676 | E13: ='PIB setorial'!I4 -> 12738.566 | F13: =IFERROR((C13*FATOR_2019)/(B13*FATOR_2016)-1,"n.d.") -> 0.057979958 | G13: =IFERROR((D13*FATOR_2022)/(C13*FATOR_2019)-1,"n.d.") -> 0.12100233 | H13: =IFERROR((E13*FATOR_2025)/(D13*FATOR_2022)-1,"n.d.") -> 0.10516708 | I13: Recessão 2015–16, pandemia em 2020 e recuperação desde 2021.
A14: Participação da agropecuária no PIB | B14: ='PIB setorial'!F22 -> 0.048913384 | C14: ='PIB setorial'!G22 -> 0.042050141 | D14: ='PIB setorial'!H22 -> 0.05767477 | E14: ='PIB setorial'!I22 -> 0.060862188 | F14: =IFERROR((C14-B14)*100,"n.d.") -> -0.68632432 | G14: =IFERROR((D14-C14)*100,"n.d.") -> 1.562463 | H14: =IFERROR((E14-D14)*100,"n.d.") -> 0.31874176 | I14: Ganho contínuo de peso relativo.
A15: Participação da indústria no PIB | B15: ='PIB setorial'!F23 -> 0.18354761 | C15: ='PIB setorial'!G23 -> 0.18754628 | D15: ='PIB setorial'!H23 -> 0.22819454 | E15: ='PIB setorial'!I23 -> 0.20149945 | F15: =IFERROR((C15-B15)*100,"n.d.") -> 0.39986637 | G15: =IFERROR((D15-C15)*100,"n.d.") -> 4.0648261 | H15: =IFERROR((E15-D15)*100,"n.d.") -> -2.6695091 | I15: Salto em 2022 puxado pela extrativa (petróleo).
A16: Participação dos serviços financeiros no PIB | B16: ='PIB setorial'!F25 -> 0.067875388 | C16: ='PIB setorial'!G25 -> 0.062293117 | D16: ='PIB setorial'!H25 -> 0.060455911 | E16: ='PIB setorial'!I25 -> 0.073027765 | F16: =IFERROR((C16-B16)*100,"n.d.") -> -0.55822708 | G16: =IFERROR((D16-C16)*100,"n.d.") -> -0.18372053 | H16: =IFERROR((E16-D16)*100,"n.d.") -> 1.2571853
A17: Participação dos serviços não financeiros no PIB | B17: ='PIB setorial'!F26 -> 0.56416151 | C17: ='PIB setorial'!G26 -> 0.56838538 | D17: ='PIB setorial'!H26 -> 0.52041643 | E17: ='PIB setorial'!I26 -> 0.52436051 | F17: =IFERROR((C17-B17)*100,"n.d.") -> 0.42238637 | G17: =IFERROR((D17-C17)*100,"n.d.") -> -4.7968946 | H17: =IFERROR((E17-D17)*100,"n.d.") -> 0.39440827 | I17: Perde participação ao longo do período.
A18: Receita líquida do Governo Central (R$ bi) | B18: ='Receitas públicas'!F16 -> 1089.15 | C18: ='Receitas públicas'!G16 -> 1347.277 | D18: ='Receitas públicas'!H16 -> 1856.102 | E18: ='Receitas públicas'!I16 -> 2332.558 | F18: =IFERROR((C18*FATOR_2019)/(B18*FATOR_2016)-1,"n.d.") -> 0.11038656 | G18: =IFERROR((D18*FATOR_2022)/(C18*FATOR_2019)-1,"n.d.") -> 0.13213509 | H18: =IFERROR((E18*FATOR_2025)/(D18*FATOR_2022)-1,"n.d.") -> 0.098966828
A19: Despesa primária do Governo Central (R$ bi) | B19: ='Despesas públicas'!F4 -> 1250.426 | C19: ='Despesas públicas'!G4 -> 1442.34 | D19: ='Despesas públicas'!H4 -> 1809.693 | E19: ='Despesas públicas'!I4 -> 2394.25 | F19: =IFERROR((C19*FATOR_2019)/(B19*FATOR_2016)-1,"n.d.") -> 0.03541547 | G19: =IFERROR((D19*FATOR_2022)/(C19*FATOR_2019)-1,"n.d.") -> 0.031075735 | H19: =IFERROR((E19*FATOR_2025)/(D19*FATOR_2022)-1,"n.d.") -> 0.15696058 | I19: Teto de gastos (2017–2022) × arcabouço (2024–).
A20: Resultado primário do Governo Central (R$ bi) | B20: ='Despesas públicas'!F12 -> -161.276 | C20: ='Despesas públicas'!G12 -> -95.065 | D20: ='Despesas públicas'!H12 -> 46.408 | E20: ='Despesas públicas'!I12 -> -61.69 | F20: =IFERROR((C20*FATOR_2019)/(B20*FATOR_2016)-1,"n.d.") -> -0.47087789 | G20: =IFERROR((D20*FATOR_2022)/(C20*FATOR_2019)-1,"n.d.") -> -1.4011673 | H20: =IFERROR((E20*FATOR_2025)/(D20*FATOR_2022)-1,"n.d.") -> -2.1624543 | I20: Déficit em 2016 e 2019, superávit em 2022, déficit em 2025.
A21: Juros nominais – setor público consolidado (R$ bi) | B21: ='Dívida e juros'!F11 -> 407.024 | C21: ='Dívida e juros'!G11 -> 367.282 | D21: ='Dívida e juros'!H11 -> 586.4 | E21: ='Dívida e juros'!I11 -> 1007.6 | F21: =IFERROR((C21*FATOR_2019)/(B21*FATOR_2016)-1,"n.d.") -> -0.19000074 | G21: =IFERROR((D21*FATOR_2022)/(C21*FATOR_2019)-1,"n.d.") -> 0.31204166 | H21: =IFERROR((E21*FATOR_2025)/(D21*FATOR_2022)-1,"n.d.") -> 0.50261655 | I21: Selic: 14,25% (2016) → 4,5% (2019) → 13,75% (2022) → 15% (2025).
A22: Dívida Bruta do Governo Geral (% PIB, BCB) | B22: ='Dívida e juros'!F7 -> 0.6984 | C22: ='Dívida e juros'!G7 -> 0.7444 | D22: ='Dívida e juros'!H7 -> 0.7168 | E22: ='Dívida e juros'!I7 -> 0.7864 | F22: =IFERROR((C22-B22)*100,"n.d.") -> 4.6 | G22: =IFERROR((D22-C22)*100,"n.d.") -> -2.76 | H22: =IFERROR((E22-D22)*100,"n.d.") -> 6.96
A23: Dívida Líquida do Setor Público (% PIB, BCB) | B23: ='Dívida e juros'!F9 -> 0.4614 | C23: ='Dívida e juros'!G9 -> 0.547 | D23: ='Dívida e juros'!H9 -> 0.5613 | E23: ='Dívida e juros'!I9 -> 0.6524 | F23: =IFERROR((C23-B23)*100,"n.d.") -> 8.56 | G23: =IFERROR((D23-C23)*100,"n.d.") -> 1.43 | H23: =IFERROR((E23-D23)*100,"n.d.") -> 9.11
A24: Investimentos federais pagos – RTN (R$ bi) | B24: ='LOA e execução orçamentária'!F14 -> 48.051 | C24: ='LOA e execução orçamentária'!G14 -> 37.82 | D24: ='LOA e execução orçamentária'!H14 -> 40.639 | E24: ='LOA e execução orçamentária'!I14 -> 69.923 | F24: =IFERROR((C24*FATOR_2019)/(B24*FATOR_2016)-1,"n.d.") -> -0.2934806 | G24: =IFERROR((D24*FATOR_2022)/(C24*FATOR_2019)-1,"n.d.") -> -0.11697135 | H24: =IFERROR((E24*FATOR_2025)/(D24*FATOR_2022)-1,"n.d.") -> 0.50463448 | I24: Mínimo em 2022.
A25: Desembolsos do BNDES (R$ bi) | B25: ='BNDES, Plano Safra e P&D'!F4 -> 88.3 | C25: ='BNDES, Plano Safra e P&D'!G4 -> 55.314 | D25: ='BNDES, Plano Safra e P&D'!H4 -> 97.5 | E25: ='BNDES, Plano Safra e P&D'!I4 -> 169.7 | F25: =IFERROR((C25*FATOR_2019)/(B25*FATOR_2016)-1,"n.d.") -> -0.4376854 | G25: =IFERROR((D25*FATOR_2022)/(C25*FATOR_2019)-1,"n.d.") -> 0.44851454 | H25: =IFERROR((E25*FATOR_2025)/(D25*FATOR_2022)-1,"n.d.") -> 0.52205798
A26: Plano Safra (R$ bi, ciclo) | B26: ='BNDES, Plano Safra e P&D'!F7 -> 232.88 | C26: ='BNDES, Plano Safra e P&D'!G7 -> 225.59 | D26: ='BNDES, Plano Safra e P&D'!H7 -> 340.88 | E26: ='BNDES, Plano Safra e P&D'!I7 -> 605.2 | F26: =IFERROR((C26*FATOR_2019)/(B26*FATOR_2016)-1,"n.d.") -> -0.13045383 | G26: =IFERROR((D26*FATOR_2022)/(C26*FATOR_2019)-1,"n.d.") -> 0.24175233 | H26: =IFERROR((E26*FATOR_2025)/(D26*FATOR_2022)-1,"n.d.") -> 0.55257064 | I26: Ciclos agrícolas, não anos civis.
A27: Saldo de empregos formais (pessoas) | B27: =Emprego!F7 -> -1321994 | C27: =Emprego!G7 -> 644079 | D27: =Emprego!H7 -> 2037982 | E27: =Emprego!I7 -> 1279498 | F27: =IFERROR(C27/B27-1,"n.d.") -> -1.4872027 | G27: =IFERROR(D27/C27-1,"n.d.") -> 2.1641802 | H27: =IFERROR(E27/D27-1,"n.d.") -> -0.37217404 | I27: Quebra Caged/Novo Caged em 2020.
A28: Bolsa Família / Auxílio Brasil pago (R$ bi) | B28: ='Políticas afirmativas e apoio'!F7 -> 27.49159 | C28: ='Políticas afirmativas e apoio'!G7 -> 32.48162 | D28: ='Políticas afirmativas e apoio'!H7 -> 113.02915 | E28: ='Políticas afirmativas e apoio'!I7 -> 171.82365 | F28: =IFERROR((C28*FATOR_2019)/(B28*FATOR_2016)-1,"n.d.") -> 0.060578503 | G28: =IFERROR((D28*FATOR_2022)/(C28*FATOR_2019)-1,"n.d.") -> 1.8596053 | H28: =IFERROR((E28*FATOR_2025)/(D28*FATOR_2022)-1,"n.d.") -> 0.32937176 | I28: Auxílio Brasil em 2022; novo Bolsa Família em 2025.
A29: Taxa média de desocupação | B29: =Emprego!F8 -> 0.115 | C29: =Emprego!G8 -> 0.119 | D29: =Emprego!H8 -> 0.093 | E29: =Emprego!I8 -> 0.056 | F29: =IFERROR((C29-B29)*100,"n.d.") -> 0.4 | G29: =IFERROR((D29-C29)*100,"n.d.") -> -2.6 | H29: =IFERROR((E29-D29)*100,"n.d.") -> -3.7
A30: Exportações (US$ bi) | B30: ='Comércio exterior'!F4 -> 179.52613 | C30: ='Comércio exterior'!G4 -> 221.12681 | D30: ='Comércio exterior'!H4 -> 334.13604 | E30: ='Comércio exterior'!I4 -> 348.27846 | F30: =IFERROR(C30/B30-1,"n.d.") -> 0.23172492 | G30: =IFERROR(D30/C30-1,"n.d.") -> 0.51106074 | H30: =IFERROR(E30/D30-1,"n.d.") -> 0.042325349
A31: Saldo comercial (US$ bi) | B31: ='Comércio exterior'!F6 -> 40.204772 | C31: ='Comércio exterior'!G6 -> 35.19884 | D31: ='Comércio exterior'!H6 -> 61.525351 | E31: ='Comércio exterior'!I6 -> 68.070029 | F31: =IFERROR(C31/B31-1,"n.d.") -> -0.12451088 | G31: =IFERROR(D31/C31-1,"n.d.") -> 0.7479369 | H31: =IFERROR(E31/D31-1,"n.d.") -> 0.10637367
A32: Para % e taxas, as colunas de variação trazem diferença em p.p.; para US$ e pessoas, variação nominal.
A34: Legenda de cores (classificação do dado)
A35: OFICIAL | B35: Dado oficial publicado (IBGE, BCB, Tesouro, RFB, MTE, MDIC, BNDES, MAPA/MDA, Siconfi, Portal da Transparência, Casa Civil)
A36: ESTIMADO | B36: Estimativa/projeção oficial ou cálculo próprio a partir de dados oficiais (soma, diferença, % aplicado ao PIB)
A37: APROXIMAÇÃO | B37: Aproximação: período, conceito ou recorte diferente do solicitado (explicado na observação)
A38: IMPRENSA/SETORIAL | B38: Cifra obtida via imprensa ou entidade setorial (Abdib, Inesc etc.), sem acesso direto à base oficial
A39: NÃO LOCALIZADO | B39: Não localizado após busca — tentativas registradas na aba 'Fontes e metodologia'
A41: Síntese das principais diferenças 2016 × 2019 × 2022 × 2025
A42: ■ 1. Economia e estrutura produtiva
A43: Em reais de dez/2025 (IPCA), o PIB foi de R$ 9,72 tri (2016) para R$ 10,28 tri (2019), R$ 11,53 tri (2022) e R$ 12,74 tri (2025). A agropecuária subiu de 4,9% do PIB em 2016 para 6,1% em 2025, com queda em 2019 (4,2%). A indústria teve pico em 2022 (22,8%), puxado pela extrativa (petróleo caro), e voltou a 20,2% em 2025. Os serviços não financeiros caíram de 56,4% para 52,4% do PIB; o setor financeiro recuou até 2022 (6,0%) e saltou em 2025 (7,3%). A FBCF foi de 15,5% do PIB (2016) a 17,8% (2022) e 16,8% (2025).
A44: ■ 2. Contas do Governo Central
...

Sheet Indicadores consolidados
A1: Indicadores consolidados – Brasil 2016 × 2019 × 2022 × 2025
A2: Valores vinculados às abas temáticas (texto verde). R$ bilhões correntes salvo indicação; correção pelo IPCA até dez/2025.
A3: Código | B3: Indicador | C3: Conceito | D3: Âmbito | E3: Unidade | F3: Brasil 2016 | G3: Brasil 2019 | H3: Brasil 2022 | I3: Brasil 2025 | J3: 2016 corrigido para preços de 2025 | K3: 2019 corrigido para preços de 2025 | L3: 2022 corrigido para preços de 2025 | M3: Variação nominal 2019→2025 | N3: Variação real 2016→2025 | O3: Variação real 2019→2025 | P3: Variação real 2022→2025 | Q3: 2016 como % do PIB | R3: 2019 como % do PIB | S3: 2022 como % do PIB | T3: 2025 como % do PIB | U3: Fonte 2016 | V3: Fonte 2019 | W3: Fonte 2022 | X3: Fonte 2025 | Y3: Data de acesso | Z3: Observações metodológicas
A4: 1 | B4: PIB total do Brasil | C4: PIB a preços de mercado, valores correntes (fluxo anual) | D4: Brasil | E4: R$ bi | F4: ='PIB setorial'!F4 -> 6269.327 | G4: ='PIB setorial'!G4 -> 7389.131 | H4: ='PIB setorial'!H4 -> 10079.676 | I4: ='PIB setorial'!I4 -> 12738.566 | J4: =IFERROR(F4*FATOR_2016,"n.d.") -> 9718.7105 | K4: =IFERROR(G4*FATOR_2019,"n.d.") -> 10282.201 | L4: =IFERROR(H4*FATOR_2022,"n.d.") -> 11526.371 | M4: =IFERROR(I4/G4-1,"n.d.") -> 0.72395996 | N4: =IFERROR(I4/J4-1,"n.d.") -> 0.31072594 | O4: =IFERROR(I4/K4-1,"n.d.") -> 0.23889487 | P4: =IFERROR(I4/L4-1,"n.d.") -> 0.10516708 | Q4: =IFERROR(F4/PIB_2016,"n.d.") -> 1 | R4: =IFERROR(G4/PIB_2019,"n.d.") -> 1 | S4: =IFERROR(H4/PIB_2022,"n.d.") -> 1 | T4: =IFERROR(I4/PIB_2025,"n.d.") -> 1 | U4: IBGE/SIDRA 1846 (S01) | V4: IBGE/SIDRA 1846 (S01) | W4: IBGE/SIDRA 1846 (S01) | X4: IBGE/SIDRA 1846 (S01) | Y4: 22/09/2026 | Z4: [OFICIAL] Soma dos 4 trimestres. Divulgação original de 2025: R$ 12,7 tri (S02); Tesouro usa R$ 12.733,6 bi (série anterior).
A5: 2 | B5: PIB da agropecuária | C5: VAB – Agropecuária total | D5: Brasil | E5: R$ bi | F5: ='PIB setorial'!F7 -> 306.654 | G5: ='PIB setorial'!G7 -> 310.714 | H5: ='PIB setorial'!H7 -> 581.343 | I5: ='PIB setorial'!I7 -> 775.297 | J5: =IFERROR(F5*FATOR_2016,"n.d.") -> 475.37502 | K5: =IFERROR(G5*FATOR_2019,"n.d.") -> 432.368 | L5: =IFERROR(H5*FATOR_2022,"n.d.") -> 664.78081 | M5: =IFERROR(I5/G5-1,"n.d.") -> 1.495211 | N5: =IFERROR(I5/J5-1,"n.d.") -> 0.63091657 | O5: =IFERROR(I5/K5-1,"n.d.") -> 0.79314149 | P5: =IFERROR(I5/L5-1,"n.d.") -> 0.16624455 | Q5: =IFERROR(F5/PIB_2016,"n.d.") -> 0.048913384 | R5: =IFERROR(G5/PIB_2019,"n.d.") -> 0.042050141 | S5: =IFERROR(H5/PIB_2022,"n.d.") -> 0.05767477 | T5: =IFERROR(I5/PIB_2025,"n.d.") -> 0.060862188 | U5: IBGE/SIDRA 1846 (S01) | V5: IBGE/SIDRA 1846 (S01) | W5: IBGE/SIDRA 1846 (S01) | X5: IBGE/SIDRA 1846 (S01) | Y5: 22/09/2026 | Z5: [OFICIAL] —
A6: 3 | B6: PIB da indústria | C6: VAB – Indústria total | D6: Brasil | E6: R$ bi | F6: ='PIB setorial'!F8 -> 1150.72 | G6: ='PIB setorial'!G8 -> 1385.804 | H6: ='PIB setorial'!H8 -> 2300.127 | I6: ='PIB setorial'!I8 -> 2566.814 | J6: =IFERROR(F6*FATOR_2016,"n.d.") -> 1783.8461 | K6: =IFERROR(G6*FATOR_2019,"n.d.") -> 1928.3885 | L6: =IFERROR(H6*FATOR_2022,"n.d.") -> 2630.2549 | M6: =IFERROR(I6/G6-1,"n.d.") -> 0.85222008 | N6: =IFERROR(I6/J6-1,"n.d.") -> 0.43892121 | O6: =IFERROR(I6/K6-1,"n.d.") -> 0.33106685 | P6: =IFERROR(I6/L6-1,"n.d.") -> -0.024119693 | Q6: =IFERROR(F6/PIB_2016,"n.d.") -> 0.18354761 | R6: =IFERROR(G6/PIB_2019,"n.d.") -> 0.18754628 | S6: =IFERROR(H6/PIB_2022,"n.d.") -> 0.22819454 | T6: =IFERROR(I6/PIB_2025,"n.d.") -> 0.20149945 | U6: IBGE/SIDRA 1846 (S01) | V6: IBGE/SIDRA 1846 (S01) | W6: IBGE/SIDRA 1846 (S01) | X6: IBGE/SIDRA 1846 (S01) | Y6: 22/09/2026 | Z6: [OFICIAL] Extrativa + transformação + eletricidade/gás/água/esgoto + construção.
A7: 4 | B7: PIB dos serviços | C7: VAB – Serviços total | D7: Brasil | E7: R$ bi | F7: ='PIB setorial'!F13 -> 3962.446 | G7: ='PIB setorial'!G13 -> 4660.166 | H7: ='PIB setorial'!H13 -> 5855.005 | I7: ='PIB setorial'!I13 -> 7609.87 | J7: =IFERROR(F7*FATOR_2016,"n.d.") -> 6142.5837 | K7: =IFERROR(G7*FATOR_2019,"n.d.") -> 6484.763 | L7: =IFERROR(H7*FATOR_2022,"n.d.") -> 6695.3502 | M7: =IFERROR(I7/G7-1,"n.d.") -> 0.63296114 | N7: =IFERROR(I7/J7-1,"n.d.") -> 0.2388712 | O7: =IFERROR(I7/K7-1,"n.d.") -> 0.1735001 | P7: =IFERROR(I7/L7-1,"n.d.") -> 0.13659028 | Q7: =IFERROR(F7/PIB_2016,"n.d.") -> 0.6320369 | R7: =IFERROR(G7/PIB_2019,"n.d.") -> 0.63067849 | S7: =IFERROR(H7/PIB_2022,"n.d.") -> 0.58087234 | T7: =IFERROR(I7/PIB_2025,"n.d.") -> 0.59738828 | U7: IBGE/SIDRA 1846 (S01) | V7: IBGE/SIDRA 1846 (S01) | W7: IBGE/SIDRA 1846 (S01) | X7: IBGE/SIDRA 1846 (S01) | Y7: 22/09/2026 | Z7: [OFICIAL] —
A8: 5 | B8: PIB das atividades financeiras, de seguros e serviços relacionados | C8: VAB | D8: Brasil | E8: R$ bi | F8: ='PIB setorial'!F17 -> 425.533 | G8: ='PIB setorial'!G17 -> 460.292 | H8: ='PIB setorial'!H17 -> 609.376 | I8: ='PIB setorial'!I17 -> 930.269 | J8: =IFERROR(F8*FATOR_2016,"n.d.") -> 659.66124 | K8: =IFERROR(G8*FATOR_2019,"n.d.") -> 640.51034 | L8: =IFERROR(H8*FATOR_2022,"n.d.") -> 696.83728 | M8: =IFERROR(I8/G8-1,"n.d.") -> 1.021041 | N8: =IFERROR(I8/J8-1,"n.d.") -> 0.4102223 | O8: =IFERROR(I8/K8-1,"n.d.") -> 0.45238716 | P8: =IFERROR(I8/L8-1,"n.d.") -> 0.33498742 | Q8: =IFERROR(F8/PIB_2016,"n.d.") -> 0.067875388 | R8: =IFERROR(G8/PIB_2019,"n.d.") -> 0.062293117 | S8: =IFERROR(H8/PIB_2022,"n.d.") -> 0.060455911 | T8: =IFERROR(I8/PIB_2025,"n.d.") -> 0.073027765 | U8: IBGE/SIDRA 1846 (S01) | V8: IBGE/SIDRA 1846 (S01) | W8: IBGE/SIDRA 1846 (S01) | X8: IBGE/SIDRA 1846 (S01) | Y8: 22/09/2026 | Z8: [OFICIAL] Separadas dos demais serviços, conforme solicitado.
A9: 6 | B9: PIB dos serviços não financeiros | C9: Serviços totais − atividades financeiras (cálculo) | D9: Brasil | E9: R$ bi | F9: ='PIB setorial'!F21 -> 3536.913 | G9: ='PIB setorial'!G21 -> 4199.874 | H9: ='PIB setorial'!H21 -> 5245.629 | I9: ='PIB setorial'!I21 -> 6679.601 | J9: =IFERROR(F9*FATOR_2016,"n.d.") -> 5482.9224 | K9: =IFERROR(G9*FATOR_2019,"n.d.") -> 5844.2527 | L9: =IFERROR(H9*FATOR_2022,"n.d.") -> 5998.513 | M9: =IFERROR(I9/G9-1,"n.d.") -> 0.5904289 | N9: =IFERROR(I9/J9-1,"n.d.") -> 0.21825561 | O9: =IFERROR(I9/K9-1,"n.d.") -> 0.14293502 | P9: =IFERROR(I9/L9-1,"n.d.") -> 0.11354282 | Q9: =IFERROR(F9/PIB_2016,"n.d.") -> 0.56416151 | R9: =IFERROR(G9/PIB_2019,"n.d.") -> 0.56838538 | S9: =IFERROR(H9/PIB_2022,"n.d.") -> 0.52041643 | T9: =IFERROR(I9/PIB_2025,"n.d.") -> 0.52436051 | U9: Cálculo sobre S01 | V9: Cálculo sobre S01 | W9: Cálculo sobre S01 | X9: Cálculo sobre S01 | Y9: 22/09/2026 | Z9: [ESTIMADO] Calculado na planilha: VAB serviços − VAB financeiro (mesma fonte e conceito).
A10: 7a | B10: Participação da agropecuária no PIB | C10: VAB da atividade ÷ PIB | D10: Brasil | E10: % | F10: ='PIB setorial'!F22 -> 0.048913384 | G10: ='PIB setorial'!G22 -> 0.042050141 | H10: ='PIB setorial'!H22 -> 0.05767477 | I10: ='PIB setorial'!I22 -> 0.060862188 | J10: n.a. | K10: n.a. | L10: n.a. | M10: =IFERROR((I10-G10)*100,"n.d.") -> 1.8812047 | N10: n.a. | O10: n.a. | P10: n.a. | Q10: n.a. | R10: n.a. | S10: n.a. | T10: n.a. | U10: Cálculo sobre S01 | V10: Cálculo sobre S01 | W10: Cálculo sobre S01 | X10: Cálculo sobre S01 | Y10: 22/09/2026 | Z10: ="[ESTIMADO] "&'PIB setorial'!AB22 -> [ESTIMADO] Participação no VAB (critério IBGE): 2016: 5,66%; 2019: 4,89%; 2022: 6,65%; 2025: 7,08%.
A11: 7b | B11: Participação da indústria no PIB | C11: VAB da atividade ÷ PIB | D11: Brasil | E11: % | F11: ='PIB setorial'!F23 -> 0.18354761 | G11: ='PIB setorial'!G23 -> 0.18754628 | H11: ='PIB setorial'!H23 -> 0.22819454 | I11: ='PIB setorial'!I23 -> 0.20149945 | J11: n.a. | K11: n.a. | L11: n.a. | M11: =IFERROR((I11-G11)*100,"n.d.") -> 1.3953171 | N11: n.a. | O11: n.a. | P11: n.a. | Q11: n.a. | R11: n.a. | S11: n.a. | T11: n.a. | U11: Cálculo sobre S01 | V11: Cálculo sobre S01 | W11: Cálculo sobre S01 | X11: Cálculo sobre S01 | Y11: 22/09/2026 | Z11: ="[ESTIMADO] "&'PIB setorial'!AB23 -> [ESTIMADO] Participação no VAB (critério IBGE): 2016: 21,23%; 2019: 21,80%; 2022: 26,33%; 2025: 23,44%.
A12: 7c | B12: Participação dos serviços financeiros no PIB | C12: VAB da atividade ÷ PIB | D12: Brasil | E12: % | F12: ='PIB setorial'!F25 -> 0.067875388 | G12: ='PIB setorial'!G25 -> 0.062293117 | H12: ='PIB setorial'!H25 -> 0.060455911 | I12: ='PIB setorial'!I25 -> 0.073027765 | J12: n.a. | K12: n.a. | L12: n.a. | M12: =IFERROR((I12-G12)*100,"n.d.") -> 1.0734648 | N12: n.a. | O12: n.a. | P12: n.a. | Q12: n.a. | R12: n.a. | S12: n.a. | T12: n.a. | U12: Cálculo sobre S01 | V12: Cálculo sobre S01 | W12: Cálculo sobre S01 | X12: Cálculo sobre S01 | Y12: 22/09/2026 | Z12: ="[ESTIMADO] "&'PIB setorial'!AB25 -> [ESTIMADO] Participação no VAB (critério IBGE): 2016: 7,85%; 2019: 7,24%; 2022: 6,98%; 2025: 8,49%.
A13: 7d | B13: Participação dos serviços não financeiros no PIB | C13: VAB da atividade ÷ PIB | D13: Brasil | E13: % | F13: ='PIB setorial'!F26 -> 0.56416151 | G13: ='PIB setorial'!G26 -> 0.56838538 | H13: ='PIB setorial'!H26 -> 0.52041643 | I13: ='PIB setorial'!I26 -> 0.52436051 | J13: n.a. | K13: n.a. | L13: n.a. | M13: =IFERROR((I13-G13)*100,"n.d.") -> -4.4024863 | N13: n.a. | O13: n.a. | P13: n.a. | Q13: n.a. | R13: n.a. | S13: n.a. | T13: n.a. | U13: Cálculo sobre S01 | V13: Cálculo sobre S01 | W13: Cálculo sobre S01 | X13: Cálculo sobre S01 | Y13: 22/09/2026 | Z13: ="[ESTIMADO] "&'PIB setorial'!AB26 -> [ESTIMADO] Participação no VAB (critério IBGE): 2016: 65,26%; 2019: 66,07%; 2022: 60,04%; 2025: 60,99%.
A14: 8 | B14: Arrecadação da União | C14: Arrecadação total das receitas federais (RFB + outros órgãos), fluxo anual | D14: União | E14: R$ bi | F14: ='Receitas públicas'!F4 -> 1289 | G14: ='Receitas públicas'!G4 -> 1537 | H14: ='Receitas públicas'!H4 -> 2218 | I14: ='Receitas públicas'!I4 -> 2886 | J14: =IFERROR(F14*FATOR_2016,"n.d.") -> 1998.2078 | K14: =IFERROR(G14*FATOR_2019,"n.d.") -> 2138.7823 | L14: =IFERROR(H14*FATOR_2022,"n.d.") -> 2536.3406 | M14: =IFERROR(I14/G14-1,"n.d.") -> 0.8776838 | N14: =IFERROR(I14/J14-1,"n.d.") -> 0.44429426 | O14: =IFERROR(I14/K14-1,"n.d.") -> 0.34936592 | P14: =IFERROR(I14/L14-1,"n.d.") -> 0.1378598 | Q14: =IFERROR(F14/PIB_2016,"n.d.") -> 0.20560421 | R14: =IFERROR(G14/PIB_2019,"n.d.") -> 0.20800822 | S14: =IFERROR(H14/PIB_2022,"n.d.") -> 0.22004676 | T14: =IFERROR(I14/PIB_2025,"n.d.") -> 0.22655611 | U14: Receita Federal (S29) | V14: Receita Federal (S12) | W14: Receita Federal (S29) | X14: Receita Federal (S12) | Y14: 22/09/2026 | Z14: [OFICIAL] Valores publicados como R$ 1,537 tri (2019) e R$ 2,886 tri (2025), sem mais casas decimais. Conceito distinto da 'receita total' do RTN (caixa do Tesouro). [2016/2022] 2016: R$ 1,289 tri; 2022: R$ 2,218 tri (publicados sem mais casas).
A15: 9 | B15: Gastos da União | C15: Despesas pagas no exercício, exceto intra-orçamentárias; inclui juros e amortização | D15: União | E15: R$ bi | F15: ='Despesas públicas'!F16 -> 1875.18 | G15: ='Despesas públicas'!G16 -> 2198.25 | H15: ='Despesas públicas'!H16 -> 2603.83 | I15: ='Despesas públicas'!I16 -> 3606.51 | J15: =IFERROR(F15*FATOR_2016,"n.d.") -> 2906.904 | K15: =IFERROR(G15*FATOR_2019,"n.d.") -> 3058.9319 | L15: =IFERROR(H15*FATOR_2022,"n.d.") -> 2977.5472 | M15: =IFERROR(I15/G15-1,"n.d.") -> 0.64062777 | N15: =IFERROR(I15/J15-1,"n.d.") -> 0.24067049 | O15: =IFERROR(I15/K15-1,"n.d.") -> 0.17900959 | P15: =IFERROR(I15/L15-1,"n.d.") -> 0.2112352 | Q15: =IFERROR(F15/PIB_2016,"n.d.") -> 0.29910388 | R15: =IFERROR(G15/PIB_2019,"n.d.") -> 0.29749777 | S15: =IFERROR(H15/PIB_2022,"n.d.") -> 0.25832477 | T15: =IFERROR(I15/PIB_2025,"n.d.") -> 0.28311742 | U15: RREO Anexo 01 (S05) | V15: RREO Anexo 01 (S05) | W15: RREO Anexo 01 (S05) | X15: S05 | Y15: 22/09/2026 | Z15: [OFICIAL] Não inclui restos a pagar pagos nem refinanciamento da dívida.
A16: 10 | B16: Receita primária do Governo Central | C16: Receita total (Tesouro + Previdência + BCB), caixa | D16: Governo Central | E16: R$ bi | F16: ='Receitas públicas'!F14 -> 1315.985 | G16: ='Receitas públicas'!G14 -> 1635.608 | H16: ='Receitas públicas'!H14 -> 2313.305 | I16: ='Receitas públicas'!I14 -> 2902.275 | J16: =IFERROR(F16*FATOR_2016,"n.d.") -> 2040.0399 | K16: =IFERROR(G16*FATOR_2019,"n.d.") -> 2275.9984 | L16: =IFERROR(H16*FATOR_2022,"n.d.") -> 2645.3243 | M16: =IFERROR(I16/G16-1,"n.d.") -> 0.77443189 | N16: =IFERROR(I16/J16-1,"n.d.") -> 0.42265599 | O16: =IFERROR(I16/K16-1,"n.d.") -> 0.27516567 | P16: =IFERROR(I16/L16-1,"n.d.") -> 0.097133902 | Q16: =IFERROR(F16/PIB_2016,"n.d.") -> 0.2099085 | R16: =IFERROR(G16/PIB_2019,"n.d.") -> 0.22135323 | S16: =IFERROR(H16/PIB_2022,"n.d.") -> 0.22950192 | T16: =IFERROR(I16/PIB_2025,"n.d.") -> 0.22783373 | U16: STN – RTN tab. 2.1 (S04) | V16: S04 | W16: STN – RTN tab. 2.1 (S04) | X16: S04 | Y16: 22/09/2026 | Z16: [OFICIAL] —
A17: 10b | B17: Receita líquida do Governo Central | C17: Receita total − transferências por repartição | D17: Governo Central | E17: R$ bi | F17: ='Receitas públicas'!F16 -> 1089.15 | G17: ='Receitas públicas'!G16 -> 1347.277 | H17: ='Receitas públicas'!H16 -> 1856.102 | I17: ='Receitas públicas'!I16 -> 2332.558 | J17: =IFERROR(F17*FATOR_2016,"n.d.") -> 1688.4003 | K17: =IFERROR(G17*FATOR_2019,"n.d.") -> 1874.777 | L17: =IFERROR(H17*FATOR_2022,"n.d.") -> 2122.5008 | M17: =IFERROR(I17/G17-1,"n.d.") -> 0.73131286 | N17: =IFERROR(I17/J17-1,"n.d.") -> 0.38151954 | O17: =IFERROR(I17/K17-1,"n.d.") -> 0.24417891 | P17: =IFERROR(I17/L17-1,"n.d.") -> 0.098966828 | Q17: =IFERROR(F17/PIB_2016,"n.d.") -> 0.17372678 | R17: =IFERROR(G17/PIB_2019,"n.d.") -> 0.18233227 | S17: =IFERROR(H17/PIB_2022,"n.d.") -> 0.18414302 | T17: =IFERROR(I17/PIB_2025,"n.d.") -> 0.18310994 | U17: STN – RTN tab. 2.1 (S04) | V17: S04 | W17: STN – RTN tab. 2.1 (S04) | X17: S04 | Y17: 22/09/2026 | Z17: [OFICIAL] —
A18: 11 | B18: Despesa primária do Governo Central | C18: Despesa total primária (RTN), caixa | D18: Governo Central | E18: R$ bi | F18: ='Despesas públicas'!F4 -> 1250.426 | G18: ='Despesas públicas'!G4 -> 1442.34 | H18: ='Despesas públicas'!H4 -> 1809.693 | I18: ='Despesas públicas'!I4 -> 2394.25 | J18: =IFERROR(F18*FATOR_2016,"n.d.") -> 1938.4103 | K18: =IFERROR(G18*FATOR_2019,"n.d.") -> 2007.0601 | L18: =IFERROR(H18*FATOR_2022,"n.d.") -> 2069.4309 | M18: =IFERROR(I18/G18-1,"n.d.") -> 0.65997615 | N18: =IFERROR(I18/J18-1,"n.d.") -> 0.23516159 | O18: =IFERROR(I18/K18-1,"n.d.") -> 0.19291398 | P18: =IFERROR(I18/L18-1,"n.d.") -> 0.15696058 | Q18: =IFERROR(F18/PIB_2016,"n.d.") -> 0.19945139 | R18: =IFERROR(G18/PIB_2019,"n.d.") -> 0.19519751 | S18: =IFERROR(H18/PIB_2022,"n.d.") -> 0.17953881 | T18: =IFERROR(I18/PIB_2025,"n.d.") -> 0.18795287 | U18: STN – RTN tab. 2.1 (S04) | V18: STN – RTN tab. 2.1 (S04) | W18: STN – RTN tab. 2.1 (S04) | X18: S04 | Y18: 22/09/2026 | Z18: [OFICIAL] —
A19: 12 | B19: Despesa total do Governo Central | C19: Soma: despesa primária (caixa, STN) + juros nominais (competência, BCB) | D19: Governo Central | E19: R$ bi | F19: ='Despesas públicas'!F14 -> 1568.788 | G19: ='Despesas públicas'!G14 -> 1752.46 | H19: ='Despesas públicas'!H14 -> 2312.927 | I19: ='Despesas públicas'!I14 -> 3286.13 | J19: =IFERROR(F19*FATOR_2016,"n.d.") -> 2431.9351 | K19: =IFERROR(G19*FATOR_2019,"n.d.") -> 2438.6015 | L19: =IFERROR(H19*FATOR_2022,"n.d.") -> 2644.8921 | M19: =IFERROR(I19/G19-1,"n.d.") -> 0.87515264 | N19: =IFERROR(I19/J19-1,"n.d.") -> 0.35124082 | O19: =IFERROR(I19/K19-1,"n.d.") -> 0.34754695 | P19: =IFERROR(I19/L19-1,"n.d.") -> 0.24244389 | Q19: =IFERROR(F19/PIB_2016,"n.d.") -> 0.25023228 | R19: =IFERROR(G19/PIB_2019,"n.d.") -> 0.23716727 | S19: =IFERROR(H19/PIB_2022,"n.d.") -> 0.22946442 | T19: =IFERROR(I19/PIB_2025,"n.d.") -> 0.25796703 | U19: Cálculo S04 | V19: Cálculo S04 | W19: Cálculo S04 | X19: Cálculo S04 | Y19: 22/09/2026 | Z19: [APROXIMAÇÃO] Indicador sem publicação oficial única. Soma critérios diferentes (caixa × competência); usar apenas como ordem de grandeza. Ver também o déficit nominal oficial na linha seguinte.
A20: 13 | B20: Dívida Pública Federal | C20: Estoque em 31/dez (interna + externa) | D20: União | E20: R$ bi | F20: ='Dívida e juros'!F4 -> 3113 | G20: ='Dívida e juros'!G4 -> 4248 | H20: ='Dívida e juros'!H4 -> 5951 | I20: ='Dívida e juros'!I4 -> 8635 | J20: =IFERROR(F20*FATOR_2016,"n.d.") -> 4825.7725 | K20: =IFERROR(G20*FATOR_2019,"n.d.") -> 5911.2215 | L20: =IFERROR(H20*FATOR_2022,"n.d.") -> 6805.123 | M20: =IFERROR(I20/G20-1,"n.d.") -> 1.0327213 | N20: =IFERROR(I20/J20-1,"n.d.") -> 0.78935082 | O20: =IFERROR(I20/K20-1,"n.d.") -> 0.460781 | P20: =IFERROR(I20/L20-1,"n.d.") -> 0.26889698 | Q20: =IFERROR(F20/PIB_2016,"n.d.") -> 0.49654453 | R20: =IFERROR(G20/PIB_2019,"n.d.") -> 0.57489846 | S20: =IFERROR(H20/PIB_2022,"n.d.") -> 0.59039596 | T20: =IFERROR(I20/PIB_2025,"n.d.") -> 0.6778628 | U20: Tesouro – RMD (S30) | V20: Tesouro – RMD (S11) | W20: Tesouro – RMD (S30) | X20: S11 | Y20: 22/09/2026 | Z20: [OFICIAL] Estoque; não somar com fluxos.
A21: 14 | B21: Dívida Bruta do Governo Geral | C21: Estoque em dez (União + estados + municípios; exclui BCB e estatais) | D21: Governo Geral | E21: R$ bi | F21: ='Dívida e juros'!F6 -> 4378.4864 | G21: ='Dívida e juros'!G6 -> 5500.1042 | H21: ='Dívida e juros'!H6 -> 7224.8822 | I21: ='Dívida e juros'!I6 -> 10017.919 | J21: =IFERROR(F21*FATOR_2016,"n.d.") -> 6787.5295 | K21: =IFERROR(G21*FATOR_2019,"n.d.") -> 7653.5625 | L21: =IFERROR(H21*FATOR_2022,"n.d.") -> 8261.8404 | M21: =IFERROR(I21/G21-1,"n.d.") -> 0.82140535 | N21: =IFERROR(I21/J21-1,"n.d.") -> 0.47593011 | O21: =IFERROR(I21/K21-1,"n.d.") -> 0.30892236 | P21: =IFERROR(I21/L21-1,"n.d.") -> 0.21255297 | Q21: =IFERROR(F21/PIB_2016,"n.d.") -> 0.69839815 | R21: =IFERROR(G21/PIB_2019,"n.d.") -> 0.74435061 | S21: =IFERROR(H21/PIB_2022,"n.d.") -> 0.71677723 | T21: =IFERROR(I21/PIB_2025,"n.d.") -> 0.7864244 | U21: BCB SGS (S08) | V21: BCB SGS 13761 (S08) | W21: BCB SGS (S08) | X21: S08 | Y21: 22/09/2026 | Z21: [OFICIAL] DBGG ≠ DPF: inclui dívida de estados/municípios e operações compromissadas do BCB; exclui títulos na carteira do BCB.
A22: 15 | B22: Dívida Líquida do Setor Público | C22: Estoque em dez (setor público consolidado, inclui BCB e estatais não financeiras) | D22: Setor público consolidado | E22: R$ bi | F22: ='Dívida e juros'!F8 -> 2892.9135 | G22: ='Dívida e juros'!G8 -> 4041.7688 | H22: ='Dívida e juros'!H8 -> 5658.0169 | I22: ='Dívida e juros'!I8 -> 8311.0858 | J22: =IFERROR(F22*FATOR_2016,"n.d.") -> 4484.5944 | K22: =IFERROR(G22*FATOR_2019,"n.d.") -> 5624.2444 | L22: =IFERROR(H22*FATOR_2022,"n.d.") -> 6470.0892 | M22: =IFERROR(I22/G22-1,"n.d.") -> 1.0562992 | N22: =IFERROR(I22/J22-1,"n.d.") -> 0.85325251 | O22: =IFERROR(I22/K22-1,"n.d.") -> 0.47772485 | P22: =IFERROR(I22/L22-1,"n.d.") -> 0.2845396 | Q22: =IFERROR(F22/PIB_2016,"n.d.") -> 0.46143924 | R22: =IFERROR(G22/PIB_2019,"n.d.") -> 0.54698838 | S22: =IFERROR(H22/PIB_2022,"n.d.") -> 0.56132924 | T22: =IFERROR(I22/PIB_2025,"n.d.") -> 0.65243496 | U22: BCB SGS (S08) | V22: BCB SGS 4478 (S08) | W22: BCB SGS (S08) | X22: S08 | Y22: 22/09/2026 | Z22: [OFICIAL] —
A23: 16 | B23: Renúncias fiscais e gastos tributários | C23: 2019: benefícios tributários efetivos (OSU). 2025: última projeção oficial (DGT Bases Efetivas) | D23: União | E23: R$ bi | F23: ='Receitas públicas'!F17 -> 271 | G23: ='Receitas públicas'!G17 -> 308.4 | H23: ='Receitas públicas'!H17 -> 461.05 | I23: ='Receitas públicas'!I17 -> 587.4 | J23: =IFERROR(F23*FATOR_2016,"n.d.") -> 420.10419 | K23: =IFERROR(G23*FATOR_2019,"n.d.") -> 429.148 | L23: =IFERROR(H23*FATOR_2022,"n.d.") -> 527.22265 | M23: =IFERROR(I23/G23-1,"n.d.") -> 0.90466926 | N23: =IFERROR(I23/J23-1,"n.d.") -> 0.39822456 | O23: =IFERROR(I23/K23-1,"n.d.") -> 0.36875857 | P23: =IFERROR(I23/L23-1,"n.d.") -> 0.11414031 | Q23: =IFERROR(F23/PIB_2016,"n.d.") -> 0.04322633 | R23: =IFERROR(G23/PIB_2019,"n.d.") -> 0.041736978 | S23: =IFERROR(H23/PIB_2022,"n.d.") -> 0.045740558 | T23: =IFERROR(I23/PIB_2025,"n.d.") -> 0.046111941 | U23: Fazenda – OSU 1ª ed. (S36) | V23: OSU 4ª ed. (S13) | W23: MPO – OSU (S36) | X23: RFB via Nota Técnica PLOA 2026 (S14) | Y23: 22/09/2026 | Z23: [ESTIMADO] 2025 é projeção (não realizado): 612,8 − 25,4 = 587,4 (4,40% PIB). Estimativa do PLOA 2025 = 544,4 (612,8 − 68,4). 2019 é valor efetivo. Divergência = diferença entre estimativa ex ante e apuração ex post. [2016/2022] 2016 e 2022 são valores apurados (ex post); 2016 da 1ª edição do OSU, sujeito a revisão.
A24: 17 | B24: Benefícios financeiros e creditícios | C24: Subsídios explícitos (financeiros) + implícitos (creditícios) | D24: União | E24: R$ bi | F24: ='Receitas públicas'!F18 -> 115 | G24: ='Receitas públicas'!G18 -> 40.05 | H24: ='Receitas públicas'!H18 -> 120.43 | I24: ='Receitas públicas'!I18 -> 172.5 | J24: =IFERROR(F24*FATOR_2016,"n.d.") -> 178.273 | K24: =IFERROR(G24*FATOR_2019,"n.d.") -> 55.730795 | L24: =IFERROR(H24*FATOR_2022,"n.d.") -> 137.71483 | M24: =IFERROR(I24/G24-1,"n.d.") -> 3.3071161 | N24: =IFERROR(I24/J24-1,"n.d.") -> -0.0323829 | O24: =IFERROR(I24/K24-1,"n.d.") -> 2.0952366 | P24: =IFERROR(I24/L24-1,"n.d.") -> 0.2525884 | Q24: =IFERROR(F24/PIB_2016,"n.d.") -> 0.018343277 | R24: =IFERROR(G24/PIB_2019,"n.d.") -> 0.0054201232 | S24: =IFERROR(H24/PIB_2022,"n.d.") -> 0.011947805 | T24: =IFERROR(I24/PIB_2025,"n.d.") -> 0.013541556 | U24: Fazenda – OSU (S36) | V24: OSU 4ª ed. (S13) – 11,5% × R$ 348,3 bi | W24: MPO – OSU (S36) | X24: Estimativa do Executivo – PLOA 2026 (S14) | Y24: 22/09/2026 | Z24: [ESTIMADO] 2019: 11,5% de R$ 348,3 bi (cálculo sobre dado oficial). 2025: estimativa do Poder Executivo, não apuração. Em 2024 (realizado, OSU 9ª ed.) financeiros+creditícios = 16,9% de R$ 678 bi ≈ R$ 114,6 bi — ordem de grandeza menor que a estimativa de 2025. [2016/2022] 2016 e 2022 apurados; 2016 inflado por subsídios implícitos do BNDES/FIES.
A25: 18 | B25: Juros nominais pagos (União, orçamento) | C25: GND 2, valor pago no exercício (caixa) | D25: União | E25: R$ bi | F25: ='Dívida e juros'!F10 -> 204.89 | G25: ='Dívida e juros'!G10 -> 285.09 | H25: ='Dívida e juros'!H10 -> 247.31 | I25: ='Dívida e juros'!I10 -> 363.47 | J25: =IFERROR(F25*FATOR_2016,"n.d.") -> 317.62047 | K25: =IFERROR(G25*FATOR_2019,"n.d.") -> 396.71142 | L25: =IFERROR(H25*FATOR_2022,"n.d.") -> 282.80541 | M25: =IFERROR(I25/G25-1,"n.d.") -> 0.27493072 | N25: =IFERROR(I25/J25-1,"n.d.") -> 0.14435319 | O25: =IFERROR(I25/K25-1,"n.d.") -> -0.083792451 | P25: =IFERROR(I25/L25-1,"n.d.") -> 0.28523003 | Q25: =IFERROR(F25/PIB_2016,"n.d.") -> 0.032681339 | R25: =IFERROR(G25/PIB_2019,"n.d.") -> 0.038582345 | S25: =IFERROR(H25/PIB_2022,"n.d.") -> 0.024535511 | T25: =IFERROR(I25/PIB_2025,"n.d.") -> 0.028533039 | U25: RREO Anexo 01 (S05) | V25: RREO Anexo 01 (S05) | W25: RREO Anexo 01 (S05) | X25: S05 | Y25: 22/09/2026 | Z25: [OFICIAL] Pagamento orçamentário; difere dos juros apropriados (competência) do BCB. Não há estatística oficial de juros 'pagos' do setor público consolidado.
A26: 19 | B26: Juros nominais líquidos (setor público consolidado) | C26: Competência, líquidos de juros ativos (BCB/NFSP) | D26: Setor público consolidado | E26: R$ bi | F26: ='Dívida e juros'!F11 -> 407.024 | G26: ='Dívida e juros'!G11 -> 367.282 | H26: ='Dívida e juros'!H11 -> 586.4 | I26: ='Dívida e juros'!I11 -> 1007.6 | J26: =IFERROR(F26*FATOR_2016,"n.d.") -> 630.96859 | K26: =IFERROR(G26*FATOR_2019,"n.d.") -> 511.0841 | L26: =IFERROR(H26*FATOR_2022,"n.d.") -> 670.56362 | M26: =IFERROR(I26/G26-1,"n.d.") -> 1.7433961 | N26: =IFERROR(I26/J26-1,"n.d.") -> 0.59690991 | O26: =IFERROR(I26/K26-1,"n.d.") -> 0.97149551 | P26: =IFERROR(I26/L26-1,"n.d.") -> 0.50261655 | Q26: =IFERROR(F26/PIB_2016,"n.d.") -> 0.064923077 | R26: =IFERROR(G26/PIB_2019,"n.d.") -> 0.04970571 | S26: =IFERROR(H26/PIB_2022,"n.d.") -> 0.058176473 | T26: =IFERROR(I26/PIB_2025,"n.d.") -> 0.079098385 | U26: BCB (S31) | V26: BCB via Agência Brasil (S09) | W26: BCB (S31) | X26: BCB via Poder360 (S10) | Y26: 22/09/2026 | Z26: [OFICIAL] Governo Central (juros nominais BCB): 310,1 (2019) e 891,9 (2025) – ver aba Despesas. 2025 inclui ganho de R$ 105,9 bi com swaps cambiais (redutor).
A27: 20 | B27: Amortizações da dívida | C27: GND 6, pago no exercício | D27: União | E27: R$ bi | F27: ='Dívida e juros'!F16 -> 271.44 | G27: ='Dívida e juros'!G16 -> 275.69 | H27: ='Dívida e juros'!H16 -> 207.09 | I27: ='Dívida e juros'!I16 -> 353.98 | J27: =IFERROR(F27*FATOR_2016,"n.d.") -> 420.78628 | K27: =IFERROR(G27*FATOR_2019,"n.d.") -> 383.63104 | L27: =IFERROR(H27*FATOR_2022,"n.d.") -> 236.81279 | M27: =IFERROR(I27/G27-1,"n.d.") -> 0.28397838 | N27: =IFERROR(I27/J27-1,"n.d.") -> -0.15876535 | O27: =IFERROR(I27/K27-1,"n.d.") -> -0.077290504 | P27: =IFERROR(I27/L27-1,"n.d.") -> 0.49476723 | Q27: =IFERROR(F27/PIB_2016,"n.d.") -> 0.043296513 | R27: =IFERROR(G27/PIB_2019,"n.d.") -> 0.037310206 | S27: =IFERROR(H27/PIB_2022,"n.d.") -> 0.020545303 | T27: =IFERROR(I27/PIB_2025,"n.d.") -> 0.027788057 | U27: RREO Anexo 01 (S05) | V27: RREO Anexo 01 (S05) | W27: RREO Anexo 01 (S05) | X27: S05 | Y27: 22/09/2026 | Z27: [OFICIAL] Fluxo; não confundir com refinanciamento (rolagem com emissão de títulos).
A28: 21 | B28: Refinanciamento da dívida | C28: Amortização paga com recursos de emissão de títulos (rolagem) | D28: União | E28: R$ bi | F28: ='Dívida e juros'!F17 -> 653.82 | G28: ='Dívida e juros'!G17 -> 476.78 | H28: ='Dívida e juros'!H17 -> 1425.07 | I28: ='Dívida e juros'!I17 -> 1417.64 | J28: =IFERROR(F28*FATOR_2016,"n.d.") -> 1013.5517 | K28: =IFERROR(G28*FATOR_2019,"n.d.") -> 663.4539 | L28: =IFERROR(H28*FATOR_2022,"n.d.") -> 1629.6045 | M28: =IFERROR(I28/G28-1,"n.d.") -> 1.973363 | N28: =IFERROR(I28/J28-1,"n.d.") -> 0.39868537 | O28: =IFERROR(I28/K28-1,"n.d.") -> 1.1367574 | P28: =IFERROR(I28/L28-1,"n.d.") -> -0.13007115 | Q28: =IFERROR(F28/PIB_2016,"n.d.") -> 0.10428871 | R28: =IFERROR(G28/PIB_2019,"n.d.") -> 0.064524502 | S28: =IFERROR(H28/PIB_2022,"n.d.") -> 0.14138054 | T28: =IFERROR(I28/PIB_2025,"n.d.") -> 0.11128725 | U28: RREO Anexo 01 (S05) | V28: RREO Anexo 01 (S05) | W28: RREO Anexo 01 (S05) | X28: S05 | Y28: 22/09/2026 | Z28: [OFICIAL] Dotação inicial: 714,09 (2019) e 1.655,91 (2025).
A29: 22 | B29: Investimentos previstos na LOA | C29: Dotação inicial (LOA) – Investimentos (GND 4) | D29: União | E29: R$ bi | F29: ='LOA e execução orçamentária'!F9 -> 45.31 | G29: ='LOA e execução orçamentária'!G9 -> 36.12 | H29: ='LOA e execução orçamentária'!H9 -> 42.36 | I29: ='LOA e execução orçamentária'!I9 -> 80.28 | J29: =IFERROR(F29*FATOR_2016,"n.d.") -> 70.239561 | K29: =IFERROR(G29*FATOR_2019,"n.d.") -> 50.262081 | L29: =IFERROR(H29*FATOR_2022,"n.d.") -> 48.43976 | M29: =IFERROR(I29/G29-1,"n.d.") -> 1.2225914 | N29: =IFERROR(I29/J29-1,"n.d.") -> 0.14294565 | O29: =IFERROR(I29/K29-1,"n.d.") -> 0.59722795 | P29: =IFERROR(I29/L29-1,"n.d.") -> 0.65731623 | Q29: =IFERROR(F29/PIB_2016,"n.d.") -> 0.007227251 | R29: =IFERROR(G29/PIB_2019,"n.d.") -> 0.0048882609 | S29: =IFERROR(H29/PIB_2022,"n.d.") -> 0.004202516 | T29: =IFERROR(I29/PIB_2025,"n.d.") -> 0.0063021222 | U29: RREO Anexo 01 (S05) | V29: RREO Anexo 01 (S05) | W29: RREO Anexo 01 (S05) | X29: RREO Anexo 01 (S05) | Y29: 22/09/2026 | Z29: [OFICIAL] Exclui intra-orçamentárias.
A30: 23 | B30: Investimentos empenhados | C30: Empenhado – Investimentos (GND 4) | D30: União | E30: R$ bi | F30: ='LOA e execução orçamentária'!F11 -> 38.08 | G30: ='LOA e execução orçamentária'!G11 -> 42.44 | H30: ='LOA e execução orçamentária'!H11 -> 51.19 | I30: ='LOA e execução orçamentária'!I11 -> 72.11 | J30: =IFERROR(F30*FATOR_2016,"n.d.") -> 59.031615 | K30: =IFERROR(G30*FATOR_2019,"n.d.") -> 59.056553 | L30: =IFERROR(H30*FATOR_2022,"n.d.") -> 58.537094 | M30: =IFERROR(I30/G30-1,"n.d.") -> 0.69910462 | N30: =IFERROR(I30/J30-1,"n.d.") -> 0.22154883 | O30: =IFERROR(I30/K30-1,"n.d.") -> 0.22103299 | P30: =IFERROR(I30/L30-1,"n.d.") -> 0.23186846 | Q30: =IFERROR(F30/PIB_2016,"n.d.") -> 0.0060740172 | R30: =IFERROR(G30/PIB_2019,"n.d.") -> 0.0057435712 | S30: =IFERROR(H30/PIB_2022,"n.d.") -> 0.0050785363 | T30: =IFERROR(I30/PIB_2025,"n.d.") -> 0.0056607628 | U30: RREO Anexo 01 (S05) | V30: RREO Anexo 01 (S05) | W30: RREO Anexo 01 (S05) | X30: RREO Anexo 01 (S05) | Y30: 22/09/2026 | Z30: [OFICIAL] —
A31: 24 | B31: Investimentos pagos | C31: Pago – Investimentos (GND 4) | D31: União | E31: R$ bi | F31: ='LOA e execução orçamentária'!F13 -> 16.8 | G31: ='LOA e execução orçamentária'!G13 -> 16.37 | H31: ='LOA e execução orçamentária'!H13 -> 19.59 | I31: ='LOA e execução orçamentária'!I13 -> 37.81 | J31: =IFERROR(F31*FATOR_2016,"n.d.") -> 26.04336 | K31: =IFERROR(G31*FATOR_2019,"n.d.") -> 22.779354 | L31: =IFERROR(H31*FATOR_2022,"n.d.") -> 22.401674 | M31: =IFERROR(I31/G31-1,"n.d.") -> 1.3097129 | N31: =IFERROR(I31/J31-1,"n.d.") -> 0.45180962 | O31: =IFERROR(I31/K31-1,"n.d.") -> 0.65983637 | P31: =IFERROR(I31/L31-1,"n.d.") -> 0.68782032 | Q31: =IFERROR(F31/PIB_2016,"n.d.") -> 0.0026797135 | R31: =IFERROR(G31/PIB_2019,"n.d.") -> 0.0022154161 | S31: =IFERROR(H31/PIB_2022,"n.d.") -> 0.0019435149 | T31: =IFERROR(I31/PIB_2025,"n.d.") -> 0.002968152 | U31: RREO Anexo 01 (S05) | V31: RREO Anexo 01 (S05) | W31: RREO Anexo 01 (S05) | X31: RREO Anexo 01 (S05) | Y31: 22/09/2026 | Z31: [OFICIAL] Pago do exercício (sem RAP).
A32: 25 | B32: Saúde prevista na LOA | C32: Dotação inicial (LOA) – Saúde (função 10) | D32: União | E32: R$ bi | F32: ='Saúde, educação e previdência'!F4 -> 108.006 | G32: ='Saúde, educação e previdência'!G4 -> 120.56 | H32: ='Saúde, educação e previdência'!H4 -> 147.204 | I32: ='Saúde, educação e previdência'!I4 -> 232.87 | J32: =IFERROR(F32*FATOR_2016,"n.d.") -> 167.4309 | K32: =IFERROR(G32*FATOR_2019,"n.d.") -> 167.76291 | L32: =IFERROR(H32*FATOR_2022,"n.d.") -> 168.3316 | M32: =IFERROR(I32/G32-1,"n.d.") -> 0.93156934 | N32: =IFERROR(I32/J32-1,"n.d.") -> 0.39084245 | O32: =IFERROR(I32/K32-1,"n.d.") -> 0.38808986 | P32: =IFERROR(I32/L32-1,"n.d.") -> 0.38340042 | Q32: =IFERROR(F32/PIB_2016,"n.d.") -> 0.017227686 | R32: =IFERROR(G32/PIB_2019,"n.d.") -> 0.016315856 | S32: =IFERROR(H32/PIB_2022,"n.d.") -> 0.014604041 | T32: =IFERROR(I32/PIB_2025,"n.d.") -> 0.018280708 | U32: RREO Anexo 02 (S06) | V32: RREO Anexo 02 (S06) | W32: RREO Anexo 02 (S06) | X32: RREO Anexo 02 (S06) | Y32: 22/09/2026 | Z32: [OFICIAL] Exclui intra-orçamentárias.
A33: 26a | B33: Saúde empenhada | C33: Empenhado – Saúde (função 10) | D33: União | E33: R$ bi | F33: ='Saúde, educação e previdência'!F6 -> 106.487 | G33: ='Saúde, educação e previdência'!G6 -> 124.11 | H33: ='Saúde, educação e previdência'!H6 -> 153.231 | I33: ='Saúde, educação e previdência'!I6 -> 238.64 | J33: =IFERROR(F33*FATOR_2016,"n.d.") -> 165.07614 | K33: =IFERROR(G33*FATOR_2019,"n.d.") -> 172.70285 | L33: =IFERROR(H33*FATOR_2022,"n.d.") -> 175.22363 | M33: =IFERROR(I33/G33-1,"n.d.") -> 0.92281041 | N33: =IFERROR(I33/J33-1,"n.d.") -> 0.4456359 | O33: =IFERROR(I33/K33-1,"n.d.") -> 0.3817954 | P33: =IFERROR(I33/L33-1,"n.d.") -> 0.36191679 | Q33: =IFERROR(F33/PIB_2016,"n.d.") -> 0.016985396 | R33: =IFERROR(G33/PIB_2019,"n.d.") -> 0.016796292 | S33: =IFERROR(H33/PIB_2022,"n.d.") -> 0.015201977 | T33: =IFERROR(I33/PIB_2025,"n.d.") -> 0.018733663 | U33: RREO Anexo 02 (S06) | V33: RREO Anexo 02 (S06) | W33: RREO Anexo 02 (S06) | X33: RREO Anexo 02 (S06) | Y33: 22/09/2026 | Z33: [OFICIAL] —
A34: 26b | B34: Saúde paga | C34: Pago – Saúde (função 10) | D34: União | E34: R$ bi | F34: ='Saúde, educação e previdência'!F8 -> 100.191 | G34: ='Saúde, educação e previdência'!G8 -> 114.182 | H34: ='Saúde, educação e previdência'!H8 -> 136.85 | I34: ='Saúde, educação e previdência'!I8 -> 234.28 | J34: =IFERROR(F34*FATOR_2016,"n.d.") -> 155.31609 | K34: =IFERROR(G34*FATOR_2019,"n.d.") -> 158.88773 | L34: =IFERROR(H34*FATOR_2022,"n.d.") -> 156.49153 | M34: =IFERROR(I34/G34-1,"n.d.") -> 1.051812 | N34: =IFERROR(I34/J34-1,"n.d.") -> 0.50840784 | O34: =IFERROR(I34/K34-1,"n.d.") -> 0.47450024 | P34: =IFERROR(I34/L34-1,"n.d.") -> 0.49707785 | Q34: =IFERROR(F34/PIB_2016,"n.d.") -> 0.015981141 | R34: =IFERROR(G34/PIB_2019,"n.d.") -> 0.015452697 | S34: =IFERROR(H34/PIB_2022,"n.d.") -> 0.013576825 | T34: =IFERROR(I34/PIB_2025,"n.d.") -> 0.018391395 | U34: Portal da Transparência (S07) | V34: Portal da Transparência (S07) | W34: Portal da Transparência (S07) | X34: Portal da Transparência (S07) | Y34: 22/09/2026 | Z34: [OFICIAL] Pago segundo o Portal da Transparência: inclui restos a pagar pagos no ano e classificação por função do Portal; pode divergir do RREO (critérios distintos).
A35: 27 | B35: Educação prevista na LOA | C35: Dotação inicial (LOA) – Educação (função 12) | D35: União | E35: R$ bi | F35: ='Saúde, educação e previdência'!F9 -> 91.627 | G35: ='Saúde, educação e previdência'!G9 -> 103.03 | H35: ='Saúde, educação e previdência'!H9 -> 112.505 | I35: ='Saúde, educação e previdência'!I9 -> 163.1 | J35: =IFERROR(F35*FATOR_2016,"n.d.") -> 142.04017 | K35: =IFERROR(G35*FATOR_2019,"n.d.") -> 143.36938 | L35: =IFERROR(H35*FATOR_2022,"n.d.") -> 128.65239 | M35: =IFERROR(I35/G35-1,"n.d.") -> 0.58303407 | N35: =IFERROR(I35/J35-1,"n.d.") -> 0.1482667 | O35: =IFERROR(I35/K35-1,"n.d.") -> 0.13762084 | P35: =IFERROR(I35/L35-1,"n.d.") -> 0.26775726 | Q35: =IFERROR(F35/PIB_2016,"n.d.") -> 0.014615125 | R35: =IFERROR(G35/PIB_2019,"n.d.") -> 0.013943453 | S35: =IFERROR(H35/PIB_2022,"n.d.") -> 0.011161569 | T35: =IFERROR(I35/PIB_2025,"n.d.") -> 0.012803639 | U35: RREO Anexo 02 (S06) | V35: RREO Anexo 02 (S06) | W35: RREO Anexo 02 (S06) | X35: RREO Anexo 02 (S06) | Y35: 22/09/2026 | Z35: [OFICIAL] Exclui intra-orçamentárias.
A36: 28a | B36: Educação empenhada | C36: Empenhado – Educação (função 12) | D36: União | E36: R$ bi | F36: ='Saúde, educação e previdência'!F11 -> 94.546 | G36: ='Saúde, educação e previdência'!G11 -> 101.3 | H36: ='Saúde, educação e previdência'!H11 -> 117.753 | I36: ='Saúde, educação e previdência'!I11 -> 176.01 | J36: =IFERROR(F36*FATOR_2016,"n.d.") -> 146.56521 | K36: =IFERROR(G36*FATOR_2019,"n.d.") -> 140.96204 | L36: =IFERROR(H36*FATOR_2022,"n.d.") -> 134.65361 | M36: =IFERROR(I36/G36-1,"n.d.") -> 0.73751234 | N36: =IFERROR(I36/J36-1,"n.d.") -> 0.20089893 | O36: =IFERROR(I36/K36-1,"n.d.") -> 0.24863406 | P36: =IFERROR(I36/L36-1,"n.d.") -> 0.30713166 | Q36: =IFERROR(F36/PIB_2016,"n.d.") -> 0.015080726 | R36: =IFERROR(G36/PIB_2019,"n.d.") -> 0.013709325 | S36: =IFERROR(H36/PIB_2022,"n.d.") -> 0.011682221 | T36: =IFERROR(I36/PIB_2025,"n.d.") -> 0.013817097 | U36: RREO Anexo 02 (S06) | V36: RREO Anexo 02 (S06) | W36: RREO Anexo 02 (S06) | X36: RREO Anexo 02 (S06) | Y36: 22/09/2026 | Z36: [OFICIAL] —
A37: 28b | B37: Educação paga | C37: Pago – Educação (função 12) | D37: União | E37: R$ bi | F37: ='Saúde, educação e previdência'!F13 -> 95.184 | G37: ='Saúde, educação e previdência'!G13 -> 94.474 | H37: ='Saúde, educação e previdência'!H13 -> 109.778 | I37: ='Saúde, educação e previdência'!I13 -> 174.587 | J37: =IFERROR(F37*FATOR_2016,"n.d.") -> 147.55423 | K37: =IFERROR(G37*FATOR_2019,"n.d.") -> 131.46345 | L37: =IFERROR(H37*FATOR_2022,"n.d.") -> 125.53399 | M37: =IFERROR(I37/G37-1,"n.d.") -> 0.84798992 | N37: =IFERROR(I37/J37-1,"n.d.") -> 0.18320563 | O37: =IFERROR(I37/K37-1,"n.d.") -> 0.32802692 | P37: =IFERROR(I37/L37-1,"n.d.") -> 0.39075477 | Q37: =IFERROR(F37/PIB_2016,"n.d.") -> 0.015182491 | R37: =IFERROR(G37/PIB_2019,"n.d.") -> 0.012785536 | S37: =IFERROR(H37/PIB_2022,"n.d.") -> 0.010891025 | T37: =IFERROR(I37/PIB_2025,"n.d.") -> 0.013705389 | U37: Portal da Transparência (S07) | V37: Portal da Transparência (S07) | W37: Portal da Transparência (S07) | X37: Portal da Transparência (S07) | Y37: 22/09/2026 | Z37: [OFICIAL] Pago segundo o Portal da Transparência: inclui restos a pagar pagos no ano e classificação por função do Portal; pode divergir do RREO (critérios distintos).
A38: 29 | B38: Segurança pública prevista na LOA | C38: Dotação inicial (LOA) – Segurança pública (função 06) | D38: União | E38: R$ bi | F38: ='Segurança e polít. afirmativas'!F4 -> 7.032 | G38: ='Segurança e polít. afirmativas'!G4 -> 10.37 | H38: ='Segurança e polít. afirmativas'!H4 -> 11.607 | I38: ='Segurança e polít. afirmativas'!I4 -> 15.62 | J38: =IFERROR(F38*FATOR_2016,"n.d.") -> 10.901006 | K38: =IFERROR(G38*FATOR_2019,"n.d.") -> 14.430171 | L38: =IFERROR(H38*FATOR_2022,"n.d.") -> 13.272906 | M38: =IFERROR(I38/G38-1,"n.d.") -> 0.50626808 | N38: =IFERROR(I38/J38-1,"n.d.") -> 0.43289525 | O38: =IFERROR(I38/K38-1,"n.d.") -> 0.082454255 | P38: =IFERROR(I38/L38-1,"n.d.") -> 0.17683348 | Q38: =IFERROR(F38/PIB_2016,"n.d.") -> 0.0011216515 | R38: =IFERROR(G38/PIB_2019,"n.d.") -> 0.0014034127 | S38: =IFERROR(H38/PIB_2022,"n.d.") -> 0.0011515251 | T38: =IFERROR(I38/PIB_2025,"n.d.") -> 0.0012261977 | U38: RREO Anexo 02 (S06) | V38: RREO Anexo 02 (S06) | W38: RREO Anexo 02 (S06) | X38: RREO Anexo 02 (S06) | Y38: 22/09/2026 | Z38: [OFICIAL] Exclui intra-orçamentárias.
A39: 30a | B39: Segurança pública empenhada | C39: Empenhado – Segurança pública (função 06) | D39: União | E39: R$ bi | F39: ='Segurança e polít. afirmativas'!F6 -> 8.816 | G39: ='Segurança e polít. afirmativas'!G6 -> 10.23 | H39: ='Segurança e polít. afirmativas'!H6 -> 13.057 | I39: ='Segurança e polít. afirmativas'!I6 -> 16.58 | J39: =IFERROR(F39*FATOR_2016,"n.d.") -> 13.666563 | K39: =IFERROR(G39*FATOR_2019,"n.d.") -> 14.235357 | L39: =IFERROR(H39*FATOR_2022,"n.d.") -> 14.931018 | M39: =IFERROR(I39/G39-1,"n.d.") -> 0.62072336 | N39: =IFERROR(I39/J39-1,"n.d.") -> 0.21317994 | O39: =IFERROR(I39/K39-1,"n.d.") -> 0.16470562 | P39: =IFERROR(I39/L39-1,"n.d.") -> 0.11043999 | Q39: =IFERROR(F39/PIB_2016,"n.d.") -> 0.0014062115 | R39: =IFERROR(G39/PIB_2019,"n.d.") -> 0.0013844659 | S39: =IFERROR(H39/PIB_2022,"n.d.") -> 0.0012953789 | T39: =IFERROR(I39/PIB_2025,"n.d.") -> 0.0013015594 | U39: RREO Anexo 02 (S06) | V39: RREO Anexo 02 (S06) | W39: RREO Anexo 02 (S06) | X39: RREO Anexo 02 (S06) | Y39: 22/09/2026 | Z39: [OFICIAL] —
A40: 30b | B40: Segurança pública paga | C40: Pago – Segurança pública (função 06) | D40: União | E40: R$ bi | F40: ='Segurança e polít. afirmativas'!F8 -> 8.423 | G40: ='Segurança e polít. afirmativas'!G8 -> 9.018 | H40: ='Segurança e polít. afirmativas'!H8 -> 11.729 | I40: ='Segurança e polít. afirmativas'!I8 -> 15.41 | J40: =IFERROR(F40*FATOR_2016,"n.d.") -> 13.057334 | K40: =IFERROR(G40*FATOR_2019,"n.d.") -> 12.548822 | L40: =IFERROR(H40*FATOR_2022,"n.d.") -> 13.412416 | M40: =IFERROR(I40/G40-1,"n.d.") -> 0.70880461 | N40: =IFERROR(I40/J40-1,"n.d.") -> 0.18017963 | O40: =IFERROR(I40/K40-1,"n.d.") -> 0.22800373 | P40: =IFERROR(I40/L40-1,"n.d.") -> 0.14893543 | Q40: =IFERROR(F40/PIB_2016,"n.d.") -> 0.0013435254 | R40: =IFERROR(G40/PIB_2019,"n.d.") -> 0.0012204412 | S40: =IFERROR(H40/PIB_2022,"n.d.") -> 0.0011636287 | T40: =IFERROR(I40/PIB_2025,"n.d.") -> 0.0012097123 | U40: Portal da Transparência (S07) | V40: Portal da Transparência (S07) | W40: Portal da Transparência (S07) | X40: Portal da Transparência (S07) | Y40: 22/09/2026 | Z40: [OFICIAL] Pago segundo o Portal da Transparência: inclui restos a pagar pagos no ano e classificação por função do Portal; pode divergir do RREO (critérios distintos).
...

Sheet PIB setorial
A1: PIB setorial – valor adicionado por atividade (valores correntes)
A2: IBGE, Contas Nacionais Trimestrais (SIDRA 1846), soma dos quatro trimestres de cada ano. Participações ao final.
A3: Código | B3: Indicador | C3: Conceito / estágio | D3: Âmbito | E3: Unidade | F3: Brasil 2016 | G3: Brasil 2019 | H3: Brasil 2022 | I3: Brasil 2025 | J3: 2016 em R$ de dez/2025 | K3: 2019 em R$ de dez/2025 | L3: 2022 em R$ de dez/2025 | M3: Variação 2016→2019 | N3: Variação 2019→2022 | O3: Variação 2022→2025 | P3: Variação 2016→2025 | Q3: Diferença absoluta 2025−2016 (nominal) | R3: Diferença absoluta 2025−2019 (nominal) | S3: 2016 % do PIB | T3: 2019 % do PIB | U3: 2022 % do PIB | V3: 2025 % do PIB | W3: Fonte 2016 | X3: Fonte 2019 | Y3: Fonte 2022 | Z3: Fonte 2025 | AA3: Classificação do dado | AB3: Observações metodológicas
A4: 1 | B4: PIB total | C4: PIB a preços de mercado, valores correntes (fluxo anual) | D4: Brasil | E4: R$ bi | F4: 6269.327 | G4: 7389.131 | H4: 10079.676 | I4: 12738.566 | J4: =IFERROR(F4*FATOR_2016,"n.d.") -> 9718.7105 | K4: =IFERROR(G4*FATOR_2019,"n.d.") -> 10282.201 | L4: =IFERROR(H4*FATOR_2022,"n.d.") -> 11526.371 | M4: =IFERROR(K4/J4-1,"n.d.") -> 0.057979958 | N4: =IFERROR(L4/K4-1,"n.d.") -> 0.12100233 | O4: =IFERROR(I4/L4-1,"n.d.") -> 0.10516708 | P4: =IFERROR(I4/J4-1,"n.d.") -> 0.31072594 | Q4: =IFERROR(I4-F4,"n.d.") -> 6469.239 | R4: =IFERROR(I4-G4,"n.d.") -> 5349.435 | S4: =IFERROR(F4/PIB_2016,"n.d.") -> 1 | T4: =IFERROR(G4/PIB_2019,"n.d.") -> 1 | U4: =IFERROR(H4/PIB_2022,"n.d.") -> 1 | V4: =IFERROR(I4/PIB_2025,"n.d.") -> 1 | W4: IBGE/SIDRA 1846 (S01) | X4: IBGE/SIDRA 1846 (S01) | Y4: IBGE/SIDRA 1846 (S01) | Z4: IBGE/SIDRA 1846 (S01) | AA4: OFICIAL | AB4: Soma dos 4 trimestres. Divulgação original de 2025: R$ 12,7 tri (S02); Tesouro usa R$ 12.733,6 bi (série anterior).
A5: 1.1 | B5: Valor adicionado bruto (VAB) a preços básicos | C5: Soma do VAB das atividades | D5: Brasil | E5: R$ bi | F5: 5419.822 | G5: 6356.683 | H5: 8736.476 | I5: 10951.982 | J5: =IFERROR(F5*FATOR_2016,"n.d.") -> 8401.8079 | K5: =IFERROR(G5*FATOR_2019,"n.d.") -> 8845.5181 | L5: =IFERROR(H5*FATOR_2022,"n.d.") -> 9990.3871 | M5: =IFERROR(K5/J5-1,"n.d.") -> 0.052811276 | N5: =IFERROR(L5/K5-1,"n.d.") -> 0.12942928 | O5: =IFERROR(I5/L5-1,"n.d.") -> 0.096252013 | P5: =IFERROR(I5/J5-1,"n.d.") -> 0.30352683 | Q5: =IFERROR(I5-F5,"n.d.") -> 5532.16 | R5: =IFERROR(I5-G5,"n.d.") -> 4595.299 | S5: =IFERROR(F5/PIB_2016,"n.d.") -> 0.86449821 | T5: =IFERROR(G5/PIB_2019,"n.d.") -> 0.86027477 | U5: =IFERROR(H5/PIB_2022,"n.d.") -> 0.86674175 | V5: =IFERROR(I5/PIB_2025,"n.d.") -> 0.85974999 | W5: IBGE/SIDRA 1846 (S01) | X5: IBGE/SIDRA 1846 (S01) | Y5: IBGE/SIDRA 1846 (S01) | Z5: IBGE/SIDRA 1846 (S01) | AA5: OFICIAL | AB5: Base para participações setoriais usadas pelo IBGE.
A6: 1.2 | B6: Impostos líquidos sobre produtos | C6: PIB − VAB | D6: Brasil | E6: R$ bi | F6: 139.32136 | G6: 1032.447 | H6: 272.61069 | I6: 1786.584 | J6: =IFERROR(F6*FATOR_2016,"n.d.") -> 215.97596 | K6: =IFERROR(G6*FATOR_2019,"n.d.") -> 1436.6815 | L6: =IFERROR(H6*FATOR_2022,"n.d.") -> 311.7374 | M6: =IFERROR(K6/J6-1,"n.d.") -> 5.6520433 | N6: =IFERROR(L6/K6-1,"n.d.") -> -0.78301565 | O6: =IFERROR(I6/L6-1,"n.d.") -> 4.7310544 | P6: =IFERROR(I6/J6-1,"n.d.") -> 7.2721427 | Q6: =IFERROR(I6-F6,"n.d.") -> 1647.2626 | R6: =IFERROR(I6-G6,"n.d.") -> 754.137 | S6: =IFERROR(F6/PIB_2016,"n.d.") -> 0.022222698 | T6: =IFERROR(G6/PIB_2019,"n.d.") -> 0.13972509 | U6: =IFERROR(H6/PIB_2022,"n.d.") -> 0.02704558 | V6: =IFERROR(I6/PIB_2025,"n.d.") -> 0.14025001 | W6: Comex Stat (S18) | X6: IBGE/SIDRA 1846 (S01) | Y6: Comex Stat (S18) | Z6: IBGE/SIDRA 1846 (S01) | AA6: OFICIAL | AB6: —
A7: 2 | B7: PIB da agropecuária (VAB) | C7: VAB – Agropecuária total | D7: Brasil | E7: R$ bi | F7: 306.654 | G7: 310.714 | H7: 581.343 | I7: 775.297 | J7: =IFERROR(F7*FATOR_2016,"n.d.") -> 475.37502 | K7: =IFERROR(G7*FATOR_2019,"n.d.") -> 432.368 | L7: =IFERROR(H7*FATOR_2022,"n.d.") -> 664.78081 | M7: =IFERROR(K7/J7-1,"n.d.") -> -0.090469672 | N7: =IFERROR(L7/K7-1,"n.d.") -> 0.53753473 | O7: =IFERROR(I7/L7-1,"n.d.") -> 0.16624455 | P7: =IFERROR(I7/J7-1,"n.d.") -> 0.63091657 | Q7: =IFERROR(I7-F7,"n.d.") -> 468.643 | R7: =IFERROR(I7-G7,"n.d.") -> 464.583 | S7: =IFERROR(F7/PIB_2016,"n.d.") -> 0.048913384 | T7: =IFERROR(G7/PIB_2019,"n.d.") -> 0.042050141 | U7: =IFERROR(H7/PIB_2022,"n.d.") -> 0.05767477 | V7: =IFERROR(I7/PIB_2025,"n.d.") -> 0.060862188 | W7: IBGE/SIDRA 1846 (S01) | X7: IBGE/SIDRA 1846 (S01) | Y7: IBGE/SIDRA 1846 (S01) | Z7: IBGE/SIDRA 1846 (S01) | AA7: OFICIAL | AB7: —
A8: 3 | B8: PIB da indústria (VAB) | C8: VAB – Indústria total | D8: Brasil | E8: R$ bi | F8: 1150.72 | G8: 1385.804 | H8: 2300.127 | I8: 2566.814 | J8: =IFERROR(F8*FATOR_2016,"n.d.") -> 1783.8461 | K8: =IFERROR(G8*FATOR_2019,"n.d.") -> 1928.3885 | L8: =IFERROR(H8*FATOR_2022,"n.d.") -> 2630.2549 | M8: =IFERROR(K8/J8-1,"n.d.") -> 0.081028506 | N8: =IFERROR(L8/K8-1,"n.d.") -> 0.36396527 | O8: =IFERROR(I8/L8-1,"n.d.") -> -0.024119693 | P8: =IFERROR(I8/J8-1,"n.d.") -> 0.43892121 | Q8: =IFERROR(I8-F8,"n.d.") -> 1416.094 | R8: =IFERROR(I8-G8,"n.d.") -> 1181.01 | S8: =IFERROR(F8/PIB_2016,"n.d.") -> 0.18354761 | T8: =IFERROR(G8/PIB_2019,"n.d.") -> 0.18754628 | U8: =IFERROR(H8/PIB_2022,"n.d.") -> 0.22819454 | V8: =IFERROR(I8/PIB_2025,"n.d.") -> 0.20149945 | W8: IBGE/SIDRA 1846 (S01) | X8: IBGE/SIDRA 1846 (S01) | Y8: IBGE/SIDRA 1846 (S01) | Z8: IBGE/SIDRA 1846 (S01) | AA8: OFICIAL | AB8: Extrativa + transformação + eletricidade/gás/água/esgoto + construção.
A9: 3.1 | B9: Indústrias extrativas | C9: VAB | D9: Brasil | E9: R$ bi | F9: 55.575 | G9: 182.817 | H9: 476.676 | I9: 403.599 | J9: =IFERROR(F9*FATOR_2016,"n.d.") -> 86.152363 | K9: =IFERROR(G9*FATOR_2019,"n.d.") -> 254.39543 | L9: =IFERROR(H9*FATOR_2022,"n.d.") -> 545.09138 | M9: =IFERROR(K9/J9-1,"n.d.") -> 1.9528549 | N9: =IFERROR(L9/K9-1,"n.d.") -> 1.1426933 | O9: =IFERROR(I9/L9-1,"n.d.") -> -0.25957553 | P9: =IFERROR(I9/J9-1,"n.d.") -> 3.6847119 | Q9: =IFERROR(I9-F9,"n.d.") -> 348.024 | R9: =IFERROR(I9-G9,"n.d.") -> 220.782 | S9: =IFERROR(F9/PIB_2016,"n.d.") -> 0.0088645879 | T9: =IFERROR(G9/PIB_2019,"n.d.") -> 0.02474134 | U9: =IFERROR(H9/PIB_2022,"n.d.") -> 0.047290806 | V9: =IFERROR(I9/PIB_2025,"n.d.") -> 0.031683237 | W9: IBGE/SIDRA 1846 (S01) | X9: IBGE/SIDRA 1846 (S01) | Y9: IBGE/SIDRA 1846 (S01) | Z9: IBGE/SIDRA 1846 (S01) | AA9: OFICIAL | AB9: —
A10: 3.2 | B10: Indústrias de transformação | C10: VAB | D10: Brasil | E10: R$ bi | F10: 676.238 | G10: 763.482 | H10: 1317.826 | I10: 1499.618 | J10: =IFERROR(F10*FATOR_2016,"n.d.") -> 1048.3041 | K10: =IFERROR(G10*FATOR_2019,"n.d.") -> 1062.4085 | L10: =IFERROR(H10*FATOR_2022,"n.d.") -> 1506.9682 | M10: =IFERROR(K10/J10-1,"n.d.") -> 0.013454436 | N10: =IFERROR(L10/K10-1,"n.d.") -> 0.41844525 | O10: =IFERROR(I10/L10-1,"n.d.") -> -0.0048775051 | P10: =IFERROR(I10/J10-1,"n.d.") -> 0.43051807 | Q10: =IFERROR(I10-F10,"n.d.") -> 823.38 | R10: =IFERROR(I10-G10,"n.d.") -> 736.136 | S10: =IFERROR(F10/PIB_2016,"n.d.") -> 0.10786453 | T10: =IFERROR(G10/PIB_2019,"n.d.") -> 0.10332501 | U10: =IFERROR(H10/PIB_2022,"n.d.") -> 0.13074091 | V10: =IFERROR(I10/PIB_2025,"n.d.") -> 0.11772267 | W10: IBGE/SIDRA 1846 (S01) | X10: IBGE/SIDRA 1846 (S01) | Y10: IBGE/SIDRA 1846 (S01) | Z10: IBGE/SIDRA 1846 (S01) | AA10: OFICIAL | AB10: —
A11: 3.3 | B11: Eletricidade e gás, água, esgoto e resíduos | C11: VAB | D11: Brasil | E11: R$ bi | F11: 143.72 | G11: 190.862 | H11: 211.586 | I11: 260.23 | J11: =IFERROR(F11*FATOR_2016,"n.d.") -> 222.79474 | K11: =IFERROR(G11*FATOR_2019,"n.d.") -> 265.59029 | L11: =IFERROR(H11*FATOR_2022,"n.d.") -> 241.95408 | M11: =IFERROR(K11/J11-1,"n.d.") -> 0.1920851 | N11: =IFERROR(L11/K11-1,"n.d.") -> -0.088994989 | O11: =IFERROR(I11/L11-1,"n.d.") -> 0.075534644 | P11: =IFERROR(I11/J11-1,"n.d.") -> 0.16802578 | Q11: =IFERROR(I11-F11,"n.d.") -> 116.51 | R11: =IFERROR(I11-G11,"n.d.") -> 69.368 | S11: =IFERROR(F11/PIB_2016,"n.d.") -> 0.022924311 | T11: =IFERROR(G11/PIB_2019,"n.d.") -> 0.025830101 | U11: =IFERROR(H11/PIB_2022,"n.d.") -> 0.020991349 | V11: =IFERROR(I11/PIB_2025,"n.d.") -> 0.020428516 | W11: IBGE/SIDRA 1846 (S01) | X11: IBGE/SIDRA 1846 (S01) | Y11: IBGE/SIDRA 1846 (S01) | Z11: IBGE/SIDRA 1846 (S01) | AA11: OFICIAL | AB11: —
A12: 3.4 | B12: Construção | C12: VAB | D12: Brasil | E12: R$ bi | F12: 275.187 | G12: 248.642 | H12: 294.04 | I12: 403.368 | J12: =IFERROR(F12*FATOR_2016,"n.d.") -> 426.59488 | K12: =IFERROR(G12*FATOR_2019,"n.d.") -> 345.99292 | L12: =IFERROR(H12*FATOR_2022,"n.d.") -> 336.24237 | M12: =IFERROR(K12/J12-1,"n.d.") -> -0.18894263 | N12: =IFERROR(L12/K12-1,"n.d.") -> -0.028181345 | O12: =IFERROR(I12/L12-1,"n.d.") -> 0.19963464 | P12: =IFERROR(I12/J12-1,"n.d.") -> -0.054447159 | Q12: =IFERROR(I12-F12,"n.d.") -> 128.181 | R12: =IFERROR(I12-G12,"n.d.") -> 154.726 | S12: =IFERROR(F12/PIB_2016,"n.d.") -> 0.043894185 | T12: =IFERROR(G12/PIB_2019,"n.d.") -> 0.033649694 | U12: =IFERROR(H12/PIB_2022,"n.d.") -> 0.029171573 | V12: =IFERROR(I12/PIB_2025,"n.d.") -> 0.031665103 | W12: IBGE/SIDRA 1846 (S01) | X12: IBGE/SIDRA 1846 (S01) | Y12: IBGE/SIDRA 1846 (S01) | Z12: IBGE/SIDRA 1846 (S01) | AA12: OFICIAL | AB12: —
